Workbook

Sheet Sheet1
A1: Var | B1: Description | C1: Formula | D1: Canonical_SMILES | E1: InChI | F1: MW | G1: Phase | H1: Version_Info | I1: MechanismTracer_ID | J1: MCM_Name | K1: RCIM_Name | L1: RCIM_Mini | M1: MCM_Formula_Match
A2: A3O2 | B2: Primary peroxy radical from C3H8 | C2: CH3CH2CH2OO | D2: CCCO[O] | E2: InChI=1S/C3H7O2/c1-2-3-5-4/h2-3H2,1H3 | F2: 75.1 | G2: Gas | J2: NC3H7O2
A3: ACET | B3: Acetone | C3: CH3C(O)CH3 | D3: CC(C)=O | E3: InChI=1S/C3H6O/c1-3(2)4/h1-2H3 | F3: 58.09 | G3: Gas | J3: CH3COCH3
A4: ACTA | B4: Acetic acid | C4: CH3C(O)OH | D4: CC(=O)O | E4: InChI=1S/C2H4O2/c1-2(3)4/h1H3,(H,3,4) | F4: 60.06 | G4: Gas | J4: CH3CO2H
A5: AERI | B5: Iodine on aerosol | C5: I | D5: None | F5: 126.9 | G5: Aerosol | J5: None
A6: ALD2 | B6: Acetaldehyde | C6: CH3CHO | D6: CC=O | E6: InChI=1S/C2H4O/c1-2-3/h2H,1H3 | F6: 44.06 | G6: Gas | J6: CH3CHO
A7: ALK4 | B7: Lumped >= C4 Alkanes | D7: CCCC | E7: InChI=1S/C4H10/c1-3-4-2/h3-4H2,1-2H3 | F7: 58.12 | G7: Gas | J7: NC4H10
A8: AONITA | B8: Aerosol-phase organonitrates from aromatics | C8: C6H6O6N | D8: None | F8: 189.12 | G8: Aerosol | J8: None
A9: AROMP4 | B9: Generic C4 product of aromatics | C9: C4H4O2 | D9: None | E9: InChI=1S/C4H4O2/c1-2-4(6)3-5/h2-3H,1H2;InChI=1S/C4H4O2/c5-3-1-2-4-6/h1-4H | F9: 68.08 | G9: Gas | J9: MALDIAL;VGLYOX | M9: BZFUONE;MALDIAL;VGLYOX
A10: AROMP5 | B10: C5 unsaturated dicarbonyl | C10: C5H6O2 | D10: None | E10: InChI=1S/C5H6O2/c1-5(4-7)2-3-6/h2-4H,1H3;InChI=1S/C5H6O2/c1-5(7)3-2-4-6/h2-4H,1H3 | F10: 98.1 | G10: Gas | J10: C4MDIAL;C5DICARB | M10: C4MDIAL;C5DICARB;PXYFUONE;TLFUONE
A11: AROMRO2 | B11: hydroxy-peroxy radical from aromatics | C11: C6H7O3 | D11: None | F11: 127 | G11: Gas | M11: C4MCODBCO2;C615CO2O;C619O;C6DCARBBO;CY6DIONO;CYC6DIONO;MC4CODBCO2
A12: ASOA1 | B12: Lumped non-volatile aerosol products of light aromatics + IVOCs | D12: None | F12: 150 | G12: Aerosol | J12: None
A13: ASOA2 | B13: Lumped non-volatile aerosol products of light aromatics + IVOCs | D13: None | F13: 150 | G13: Aerosol | J13: None
A14: ASOA3 | B14: Lumped non-volatile aerosol products of light aromatics + IVOCs | D14: None | F14: 150 | G14: Aerosol | J14: None
A15: ASOAN | B15: Lumped non-volatile aerosol products of light aromatics + IVOCs | D15: None | F15: 150 | G15: Aerosol | J15: None
A16: ASOG1 | B16: Lumped non-volatile gas products of light aromatics + IVOCs | D16: None | F16: 150 | G16: Gas | J16: None
A17: ASOG2 | B17: Lumped non-volatile gas products of light aromatics + IVOCs | D17: None | F17: 150 | G17: Gas | J17: None
A18: ASOG3 | B18: Lumped non-volatile gas products of light aromatics + IVOCs | D18: None | F18: 150 | G18: Gas | J18: None
A19: ATO2 | B19: Peroxy radical from acetone | C19: CH3C(O)CH2O2 | D19: CC(=O)CO[O] | E19: InChI=1S/C3H5O3/c1-3(4)2-6-5/h2H2,1H3 | F19: 89.08 | G19: Gas | J19: CH3COCH2O2
A20: ATOOH | B20: ATO2 Peroxide / Hydroperoxyacetone;ATO2 peroxide | C20: C3H6O3;CH3C(O)CH2OOH | D20: CC(=O)COO | E20: InChI=1S/C3H6O3/c1-3(4)2-6-5/h5H,2H2,1H3 | F20: 90.09 | G20: Gas | J20: HYPERACET | K20: HPAC | L20: HPAC
A21: AlF1 | C21: Al | D21: None | F21: 26.98 | G21: Aerosol | J21: None
A22: AlF2 | C22: Al | D22: None | F22: 26.98 | G22: Aerosol | J22: None
A23: AsF1 | C23: As | D23: None | F23: 74.92 | G23: Aerosol | J23: None
A24: AsF2 | C24: As | D24: None | F24: 74.92 | G24: Aerosol | J24: None
A25: B3O2 | B25: B3O2 | C25: CH3CH(OO)CH3 | D25: CC(C)O[O] | E25: InChI=1S/C3H7O2/c1-3(2)5-4/h3H,1-2H3 | F25: 75.1 | G25: Gas | J25: IC3H7O2
A26: BALD | B26: Benzaldehyde | C26: C7H6O | D26: O=Cc1ccccc1 | E26: InChI=1S/C7H6O/c8-6-7-4-2-1-3-5-7/h1-6H | F26: 106.12 | G26: Gas | J26: BENZAL | M26: BENZAL
A27: BCPI | B27: Hydrophilic black carbon aerosol | C27: C | D27: None | F27: 12.01 | G27: Aerosol | J27: None
A28: BCPO | B28: Hydrophobic black carbon aerosol | C28: C | D28: None | F28: 12.01 | G28: Aerosol | J28: None
A29: BENZ | B29: Benzene | C29: C6H6 | D29: c1ccccc1 | E29: InChI=1S/C6H6/c1-2-4-6-5-3-1/h1-6H | F29: 78.12 | G29: Gas | J29: BENZENE
A30: BENZO | B30: alkoxy radical from aromatics | C30: C6H5O | D30: [O]c1ccccc1 | E30: InChI=1S/C6H5O/c7-6-4-2-1-3-5-6/h1-5H | F30: 93 | G30: Gas | J30: C6H5O | M30: C6H5O
A31: BENZO2 | B31: peroxy radical from aromatics | C31: C6H5O2 | D31: [O]Oc1ccccc1 | E31: InChI=1S/C6H5O2/c7-8-6-4-2-1-3-5-6/h1-5H | F31: 109 | G31: Gas | J31: C6H5O2 | M31: C6H5O2;CATEC1O
A32: BENZP | B32: Phenyl hydroperoxide | C32: C6H6O2 | D32: OOc1ccccc1 | E32: InChI=1S/C6H6O2/c7-8-6-4-2-1-3-5-6/h1-5,7H | F32: 110.11 | G32: Gas | J32: C6H5OOH | M32: C6H5OOH;CATECHOL
A33: BRO2 | B33: Peroxy radical from BENZ oxidation | C33: C6H7O5 | D33: [O]OC1C=CC2OOC1C2O | E33: InChI=1S/C6H7O5/c7-5-3-1-2-4(9-8)6(5)11-10-3/h1-7H | F33: 159.13 | G33: Gas | J33: BZBIPERO2 | M33: ACCOCOETO;ACCOMCOMO;BZBIPERO2;BZEMUCO;C23C54CO3;C511CO3;C512CO3;C5CO34CO3;C6145COO2;C616O2;C620O2;C62O2;C6COCHOCO3;C6OTKETO;C6TRONOHO;CO234C65O2;CO235C6O2;CO356OCO;CY6TRIONO2;DMMALYO;EMALANHYO;EPXKTMCO3;EPXM2DLCO3;EPXMKTCO3;PHENO
A34: BZCO3 | B34: Acyl peroxy radical from benzaldehyde | C34: C7H5O3 | D34: [O]OC(=O)c1ccccc1 | E34: InChI=1S/C7H5O3/c8-7(10-9)6-4-2-1-3-5-6/h1-5H | F34: 137 | G34: Gas | J34: C6H5CO3 | M34: C6H5CO3
A35: BZCO3H | B35: Perbenzoic acid | C35: C6H5CO3H | D35: O=C(OO)c1ccccc1 | E35: InChI=1S/C7H6O3/c8-7(10-9)6-4-2-1-3-5-6/h1-5,9H | F35: 138.12 | G35: Gas | J35: C6H5CO3H
A36: BZPAN | B36: Peroxybenzoylnitrate | C36: C7H5O5N | D36: O=C(O[N+](=O)[O-])c1cccc2ooc12 | E36: InChI=1S/C7H3NO6/c9-7(12-8(10)11)4-2-1-3-5-6(4)14-13-5/h1-3H | F36: 183.12 | G36: Gas
A37: Be10 | B37: Beryllium-10 isotope | C37: Be10 | D37: None | F37: 10 | G37: Aerosol | J37: None
A38: Be10Strat | B38: Beryllium-10 isotope in stratosphere | C38: Be10 | D38: None | F38: 10 | G38: Aerosol | J38: None
A39: Be7 | B39: Beryllium-7 isotope | C39: Be7 | D39: None | F39: 7 | G39: Aerosol | J39: None
A40: Be7Strat | B40: Beryllium-7 isotope in stratosphere | C40: Be7 | D40: None | F40: 7 | G40: Aerosol | J40: None
...

Sheet Sheet2
B1: Formula | C1: FullName | D1: MW_g | E1: Phase | F1: INCHI
A2: ACR | B2: C3H4O | C2: Acrolein | D2: 56.06 | E2: Gas | F2: InChI=1S/C3H4O/c1-2-3-4/h2-3H,1H2
A3: Br | B3: Br | C3: Atomic bromine | D3: 79.9 | E3: =_xlfn.XLOOKUP(A3,Sheet1!A$2:A$800,Sheet1!G$2:G$800, "") -> Gas | F3: InChI=1S/Br
A4: Br2 | B4: Br2 | C4: Molecular Bromine | D4: 159.8 | E4: =_xlfn.XLOOKUP(A4,Sheet1!A$2:A$800,Sheet1!G$2:G$800, "") -> Gas | F4: InChI=1S/Br2/c1-2
A5: BrCl | B5: BrCl | C5: Bromine chloride | D5: 115.45 | E5: =_xlfn.XLOOKUP(A5,Sheet1!A$2:A$800,Sheet1!G$2:G$800, "") -> Gas | F5: InChI=1S/BrCl/c1-2
A6: HBr | B6: HBr | C6: Hypobromic acid | D6: 80.91 | E6: =_xlfn.XLOOKUP(A6,Sheet1!A$2:A$800,Sheet1!G$2:G$800, "") -> Gas | F6: InChI=1S/BrH/h1H
A7: BrSALA | B7: Br | C7: Fine sea salt bromine | D7: 79.9 | E7: =_xlfn.XLOOKUP(A7,Sheet1!A$2:A$800,Sheet1!G$2:G$800, "") -> Aerosol | F7: InChI=1S/BrH/h1H/p-1
A8: BrSALC | B8: Br | C8: Coarse sea salt bromine | D8: 79.9 | E8: =_xlfn.XLOOKUP(A8,Sheet1!A$2:A$800,Sheet1!G$2:G$800, "") -> Aerosol | F8: InChI=1S/BrH/h1H/p-1
A9: HOBr | B9: HOBr | C9: Hypobromous acid | D9: 96.91 | E9: =_xlfn.XLOOKUP(A9,Sheet1!A$2:A$800,Sheet1!G$2:G$800, "") -> Gas | F9: InChI=1S/BrHO/c1-2/h2H
A10: IBr | B10: IBr | C10: Iodine monobromide | D10: 206.9 | E10: =_xlfn.XLOOKUP(A10,Sheet1!A$2:A$800,Sheet1!G$2:G$800, "") -> Gas | F10: InChI=1S/BrI/c1-2
A11: BrNO2 | B11: BrNO2 | C11: Nitryl bromide | D11: 125.91 | E11: =_xlfn.XLOOKUP(A11,Sheet1!A$2:A$800,Sheet1!G$2:G$800, "") -> Gas | F11: InChI=1S/BrNO2/c1-4-2-3
A12: BrNO3 | B12: BrNO3 | C12: Bromine nitrate | D12: 141.91 | E12: =_xlfn.XLOOKUP(A12,Sheet1!A$2:A$800,Sheet1!G$2:G$800, "") -> Gas | F12: InChI=1S/BrNO3/c1-5-2(3)4
A13: BrO | B13: BrO | C13: Bromine monoxide | D13: 95.9 | E13: =_xlfn.XLOOKUP(A13,Sheet1!A$2:A$800,Sheet1!G$2:G$800, "") -> Gas | F13: InChI=1S/BrO/c1-2
A14: MONITA | C14: Aer-phase organic nitrate from monoterpene precursors | D14: 14.01 | E14: =_xlfn.XLOOKUP(A14,Sheet1!A$2:A$800,Sheet1!G$2:G$800, "") -> Aerosol | F14: InChI=1S/C10H15NO4/c1-9(2)6-4-7(9)10(3,8(12)5-6)15-11(13)14/h6-7H,4-5H2,1-3H3;InChI=1S/C10H15NO4/c1-9(2)7-3-4-10(6-12,8(9)5-7)15-11(13)14/h6-8H,3-5H2,1-2H3;InChI=1S/C10H15NO5/c1-7(13)8-6-10(4-5-12,9(8,2)3)16-11(14)15/h5,8H,4,6H2,1-3H3;InChI=1S/C10H15NO6/c1-7(13)9(14)6-8(4-5-12)10(2,3)17-11(15)16/h5,8H,4,6H2,1-3H3;InChI=1S/C10H15NO6/c1-7(13)9(6-8(14)4-5-12)10(2,3)17-11(15)16/h5,9H,4,6H2,1-3H3;InChI=1S/C10H15NO6/c1-8(2)6-4-10(8,17-15)5-7(12)9(6,3)16-11(13)14/h6,15H,4-5H2,1-3H3;InChI=1S/C10H15NO6/c1-9(2)6-3-4-10(7(9)5-6,8(12)16-15)17-11(13)14/h6-7,15H,3-5H2,1-2H3;InChI=1S/C10H15NO7/c1-9(2,18-16)7-4-6(12)5-8(13)10(7,3)17-11(14)15/h7,16H,4-5H2,1-3H3;InChI=1S/C10H17NO4/c1-10(2,15-11(13)14)9-5-3-8(7-12)4-6-9/h3,9,12H,4-7H2,1-2H3;InChI=1S/C10H17NO4/c1-7(2)8-4-5-10(3,12)9(6-8)15-11(13)14/h8-9,12H,1,4-6H2,2-3H3;InChI=1S/C10H17NO4/c1-7(2)8-4-5-10(3,9(12)6-8)15-11(13)14/h8-9,12H,1,4-6H2,2-3H3;InChI=1S/C10H17NO4/c1-7-4-5-8(6-9(7)12)10(2,3)15-11(13)14/h4,8-9,12H,5-6H2,1-3H3;InChI=1S/C10H17NO4/c1-8-3-5-9(6-4-8)10(2,7-12)15-11(13)14/h3,9,12H,4-7H2,1-2H3;InChI=1S/C10H17NO4/c1-9(2)6-4-7(9)10(3,12)8(5-6)15-11(13)14/h6-8,12H,4-5H2,1-3H3;InChI=1S/C10H17NO4/c1-9(2)6-4-7(9)10(3,8(12)5-6)15-11(13)14/h6-8,12H,4-5H2,1-3H3;InChI=1S/C10H17NO4/c1-9(2)7-3-4-10(12,8(9)5-7)6-15-11(13)14/h7-8,12H,3-6H2,1-2H3;InChI=1S/C10H17NO4/c1-9(2)7-3-4-10(6-12,8(9)5-7)15-11(13)14/h7-8,12H,3-6H2,1-2H3;InChI=1S/C10H17NO5/c1-7(2)8-4-5-10(3,16-14)9(6-8)15-11(12)13/h8-9,14H,1,4-6H2,2-3H3;InChI=1S/C10H17NO5/c1-9(2)6-4-7(9)10(3,16-11(12)13)8(5-6)15-14/h6-8,14H,4-5H2,1-3H3;InChI=1S/C10H17NO5/c1-9(2)6-4-7(9)10(3,16-14)8(5-6)15-11(12)13/h6-8,14H,4-5H2,1-3H3;InChI=1S/C10H17NO5/c1-9(2)7-3-4-10(16-14,8(9)5-7)6-15-11(12)13/h7-8,14H,3-6H2,1-2H3;InChI=1S/C10H17NO5/c1-9(2)7-3-4-10(6-15-14,8(9)5-7)16-11(12)13/h7-8,14H,3-6H2,1-2H3;InChI=1S/C10H17NO6/c1-8(13)3-4-9(5-6-12)10(2,14)7-17-11(15)16/h6,9,14H,3-5,7H2,1-2H3;InChI=1S/C10H17NO6/c1-8(14)3-4-9(5-6-12)10(2,7-13)17-11(15)16/h6,9,13H,3-5,7H2,1-2H3;InChI=1S/C10H17NO7/c1-8(13)3-4-9(5-6-12)10(2,18-16)7-17-11(14)15/h6,9,16H,3-5,7H2,1-2H3;InChI=1S/C2H5NO4/c4-1-2-7-3(5)6/h4H,1-2H2;InChI=1S/C3H5NO5/c1-3(9-7)2-8-4(5)6/h2H2,1H3;InChI=1S/C4H5NO5/c1-3(7)4(2-6)10-5(8)9/h2,4H,1H3;InChI=1S/C4H5NO5/c1-4(2-6,3-7)10-5(8)9/h2-3H,1H3;InChI=1S/C4H5NO6/c1-4(2-6,3(7)8)11-5(9)10/h2H,1H3,(H,7,8);InChI=1S/C4H5NO7/c1-2(6)3(4(7)12-10)11-5(8)9/h3,10H,1H3;InChI=1S/C4H5NO7/c1-4(2-6,3(7)11-10)12-5(8)9/h2,10H,1H3;InChI=1S/C4H7NO4/c1-4(6)2-3-9-5(7)8/h2-3H2,1H3;InChI=1S/C4H7NO6/c1-3(11-9)4(2-6)10-5(7)8/h4,6H,2H2,1H3;InChI=1S/C4H7NO6/c1-4(8,3(6)7)2-11-5(9)10/h8H,2H2,1H3,(H,6,7);InChI=1S/C4H9NO4/c1-4(2,6)3-9-5(7)8/h6H,3H2,1-2H3;InChI=1S/C5H11NO6/c1-5(9,3-8)4(2-7)12-6(10)11/h4,7-9H,2-3H2,1H3;InChI=1S/C5H11NO6/c1-5(9,4(8)2-7)3-12-6(10)11/h4,7-9H,2-3H2,1H3;InChI=1S/C5H7NO5/c7-3-1-5(2-4-8)11-6(9)10/h3-5H,1-2H2;InChI=1S/C5H7NO5/c7-3-1-5(8)2-4-11-6(9)10/h3H,1-2,4H2;InChI=1S/C5H7NO6/c1-5(3-8,4(9)2-7)12-6(10)11/h2-4,9H,1H3;InChI=1S/C5H7NO6/c1-5(9,3-8)4(2-7)12-6(10)11/h2-4,9H,1H3;InChI=1S/C5H7NO6/c1-5(9,4(8)2-7)3-12-6(10)11/h2,9H,3H2,1H3;InChI=1S/C5H7NO7/c1-5(13-10)3(12-6(8)9)2-11-4(5)7/h3,10H,2H2,1H3;InChI=1S/C5H7NO7/c1-5(2-7,13-6(11)12)3(8)4(9)10/h2-3,8H,1H3,(H,9,10);InChI=1S/C5H7NO7/c1-5(4(9)10,3(8)2-7)13-6(11)12/h2-3,8H,1H3,(H,9,10);InChI=1S/C5H7NO8/c1-5(2-7,14-6(10)11)3(8)4(9)13-12/h2-3,8,12H,1H3;InChI=1S/C5H7NO8/c1-5(3(8)2-7,4(9)13-12)14-6(10)11/h2-3,8,12H,1H3;InChI=1S/C5H7NO8/c1-5(9,4(8)14-12)3(2-7)13-6(10)11/h2-3,9,12H,1H3;InChI=1S/C5H8N2O10/c1-5(2-8,17-7(12)13)3(4(9)16-14)15-6(10)11/h3,8,14H,2H2,1H3;InChI=1S/C5H8N2O10/c1-5(4(9)16-14,17-7(12)13)3(2-8)15-6(10)11/h3,8,14H,2H2,1H3;InChI=1S/C5H8N2O10/c1-5(9,2-15-6(10)11)3(4(8)17-14)16-7(12)13/h3,9,14H,2H2,1H3;InChI=1S/C5H8N2O8/c1-5(3-9,15-7(12)13)4(2-8)14-6(10)11/h2,4,9H,3H2,1H3;InChI=1S/C5H8N2O8/c1-5(3-9,15-7(12)13)4(2-8)14-6(10)11/h3-4,8H,2H2,1H3;InChI=1S/C5H8N2O9/c1-5(10,2-15-6(11)12)3(4(8)9)16-7(13)14/h3,10H,2H2,1H3,(H,8,9);InChI=1S/C5H8N2O9/c1-5(2-8,16-7(13)14)3(4(9)10)15-6(11)12/h3,8H,2H2,1H3,(H,9,10);InChI=1S/C5H8N2O9/c1-5(4(9)10,16-7(13)14)3(2-8)15-6(11)12/h3,8H,2H2,1H3,(H,9,10);InChI=1S/C5H9NO5/c1-4(8)5(2-7)3-11-6(9)10/h5,7H,2-3H2,1H3;InChI=1S/C5H9NO6/c1-5(3-8,4(9)2-7)12-6(10)11/h2,4,8-9H,3H2,1H3;InChI=1S/C5H9NO6/c1-5(9,3-8)4(2-7)12-6(10)11/h3-4,7,9H,2H2,1H3;InChI=1S/C5H9NO6/c1-5(9,4(8)2-7)3-12-6(10)11/h7,9H,2-3H2,1H3;InChI=1S/C5H9NO7/c1-5(2-7,13-6(11)12)3(8)4(9)10/h3,7-8H,2H2,1H3,(H,9,10);InChI=1S/C5H9NO7/c1-5(4(9)10,3(8)2-7)13-6(11)12/h3,7-8H,2H2,1H3,(H,9,10);InChI=1S/C5H9NO8/c1-5(2-7,14-6(10)11)3(8)4(9)13-12/h3,7-8,12H,2H2,1H3;InChI=1S/C5H9NO8/c1-5(3(8)2-7,4(9)13-12)14-6(10)11/h3,7-8,12H,2H2,1H3;InChI=1S/C5H9NO8/c1-5(9,4(8)14-12)3(2-7)13-6(10)11/h3,7,9,12H,2H2,1H3;InChI=1S/C5H9NO9/c1-5(15-12,4(8)14-11)3(2-7)13-6(9)10/h3,7,11-12H,2H2,1H3;InChI=1S/C6H11NO4/c1-5(2)6(3-4-8)11-7(9)10/h6,8H,1,3-4H2,2H3;InChI=1S/C6H11NO4/c1-5(2)6(3-8)4-11-7(9)10/h6,8H,1,3-4H2,2H3;InChI=1S/C6H11NO6/c1-6(10,4-13-7(11)12)5(2-8)3-9/h2,5,9-10H,3-4H2,1H3;InChI=1S/C6H11NO6/c1-6(4-10,13-7(11)12)5(2-8)3-9/h2,5,9-10H,3-4H2,1H3;InChI=1S/C6H11NO7/c1-6(14-12,4-13-7(10)11)5(2-8)3-9/h2,5,9,12H,3-4H2,1H3;InChI=1S/C6H9NO5/c1-5(9)6(2-3-8)4-12-7(10)11/h3,6H,2,4H2,1H3;InChI=1S/C6H9NO6/c1-4(9)6(10)2-5(3-8)13-7(11)12/h5,8H,2-3H2,1H3;InChI=1S/C7H11NO4/c1-5-2-3-6(4-7(5)9)12-8(10)11/h2,6-7,9H,3-4H2,1H3;InChI=1S/C7H11NO4/c1-6(2)7(3-4-9)5-12-8(10)11/h4,7H,1,3,5H2,2H3;InChI=1S/C7H11NO5/c1-6(10)7(2-4-9)3-5-13-8(11)12/h4,7H,2-3,5H2,1H3;InChI=1S/C7H11NO5/c1-7(2,5-9)6(10)3-4-13-8(11)12/h5H,3-4H2,1-2H3;InChI=1S/C7H11NO6/c1-5(9)6(2-3-7(10)11)4-14-8(12)13/h6H,2-4H2,1H3,(H,10,11);InChI=1S/C7H11NO6/c1-7(14-8(12)13)5(10)2-4(9)3-6(7)11/h5-6,10-11H,2-3H2,1H3;InChI=1S/C7H13NO6/c1-7(11,5-14-8(12)13)6(4-10)2-3-9/h3,6,10-11H,2,4-5H2,1H3;InChI=1S/C7H13NO6/c1-7(11,5-14-8(12)13)6(4-10)2-3-9/h4,6,9,11H,2-3,5H2,1H3;InChI=1S/C7H13NO6/c1-7(5-11,14-8(12)13)6(4-10)2-3-9/h3,6,10-11H,2,4-5H2,1H3;InChI=1S/C7H13NO6/c1-7(5-11,14-8(12)13)6(4-10)2-3-9/h4,6,9,11H,2-3,5H2,1H3;InChI=1S/C7H13NO7/c1-7(15-13,5-14-8(11)12)6(4-10)2-3-9/h3,6,10,13H,2,4-5H2,1H3;InChI=1S/C7H13NO7/c1-7(15-13,5-14-8(11)12)6(4-10)2-3-9/h4,6,9,13H,2-3,5H2,1H3;InChI=1S/C7H7NO6/c1-7(14-8(12)13)5(10)2-4(9)3-6(7)11/h2-3H2,1H3;InChI=1S/C7H7NO8/c1-7(16-8(12)13)4(10)2-3(9)5(15-14)6(7)11/h5,14H,2H2,1H3;InChI=1S/C7H7NO9/c1-7(6(12)16-15,17-8(13)14)5(11)2-4(10)3-9/h3,15H,2H2,1H3;InChI=1S/C7H9NO6/c1-5(10)7(11)4-6(2-3-9)14-8(12)13/h3,6H,2,4H2,1H3;InChI=1S/C7H9NO7/c1-7(15-8(11)12)5(10)2-4(9)3-6(7)14-13/h6,13H,2-3H2,1H3;InChI=1S/C8H13NO3/c1-8(2)5-3-6(8)7(4-5)12-9(10)11/h5-7H,3-4H2,1-2H3;InChI=1S/C8H13NO4/c1-7(2)8(3-5-10)4-6-13-9(11)12/h5,8H,1,3-4,6H2,2H3;InChI=1S/C8H13NO4/c1-8(2)6(3-4-10)5-7(8)13-9(11)12/h4,6-7H,3,5H2,1-2H3;InChI=1S/C8H13NO5/c1-6(10)3-4-8(7(2)11)5-14-9(12)13/h8H,3-5H2,1-2H3;InChI=1S/C8H13NO5/c1-6(2)7(3-4-8(10)11)5-14-9(12)13/h7H,1,3-5H2,2H3,(H,10,11);InChI=1S/C8H13NO5/c1-8(2)5(4-14-9(12)13)3-6(8)7(10)11/h5-6H,3-4H2,1-2H3,(H,10,11);InChI=1S/C8H13NO5/c1-8(2,14-9(12)13)7(3-5-10)4-6-11/h5-7H,3-4H2,1-2H3;InChI=1S/C8H13NO6/c1-8(12,6-15-9(13)14)7(2-4-10)3-5-11/h4-5,7,12H,2-3,6H2,1H3;InChI=1S/C8H13NO6/c1-8(6-12,15-9(13)14)7(2-4-10)3-5-11/h4-5,7,12H,2-3,6H2,1H3;InChI=1S/C8H13NO7/c1-8(16-14,6-15-9(12)13)7(2-4-10)3-5-11/h4-5,7,14H,2-3,6H2,1H3;InChI=1S/C8H13NO7/c1-8(2,16-9(14)15)5(4-10)3-6(11)7(12)13/h5,10H,3-4H2,1-2H3,(H,12,13);InChI=1S/C9H11NO5/c1-9(2)6-4(11)3-5(12)7(9)8(6)15-10(13)14/h6-8H,3H2,1-2H3;InChI=1S/C9H13NO4/c1-8(2)6-5-9(8,14-10(12)13)4-3-7(6)11/h6H,3-5H2,1-2H3;InChI=1S/C9H13NO4/c1-9(2)5-3-4-6(11)7(9)8(5)14-10(12)13/h5,7-8H,3-4H2,1-2H3;InChI=1S/C9H13NO4/c1-9(2)5-3-6(9)8(4-7(5)11)14-10(12)13/h5-6,8H,3-4H2,1-2H3;InChI=1S/C9H13NO5/c1-9(2)6(5-11)7(12)3-4-8(9)15-10(13)14/h5-6,8H,3-4H2,1-2H3;InChI=1S/C9H13NO5/c1-9(2)6(7(12)3-4-11)5-8(9)15-10(13)14/h4,6,8H,3,5H2,1-2H3;InChI=1S/C9H13NO5/c1-9(2,15-10(13)14)7-5-6(11)3-4-8(7)12/h7H,3-5H2,1-2H3;InChI=1S/C9H13NO6/c1-9(2,16-10(14)15)7(3-5-11)8(13)4-6-12/h5-7H,3-4H2,1-2H3;InChI=1S/C9H13NO6/c1-9(2,16-10(14)15)7(6-12)8(13)4-3-5-11/h5-7H,3-4H2,1-2H3;InChI=1S/C9H15NO4/c1-6(11)8-4-7(9(8,2)3)5-14-10(12)13/h7-8H,4-5H2,1-3H3;InChI=1S/C9H15NO4/c1-7(2)9(5-4-8(3)11)6-14-10(12)13/h9H,1,4-6H2,2-3H3;InChI=1S/C9H15NO5/c1-6(11)7-3-4-9(2,12)8(5-7)15-10(13)14/h7-8,12H,3-5H2,1-2H3;InChI=1S/C9H15NO5/c1-6(11)7-3-4-9(2,8(12)5-7)15-10(13)14/h7-8,12H,3-5H2,1-2H3;InChI=1S/C9H15NO6/c1-6(11)7-3-4-9(2,16-14)8(5-7)15-10(12)13/h7-8,14H,3-5H2,1-2H3;InChI=1S/C9H15NO6/c1-6(12)8(13)4-7(5-11)9(2,3)16-10(14)15/h7,11H,4-5H2,1-3H3
A15: MTPA | C15: a-pinene, b-pinene, sabinene, carene | D15: 136.26 | E15: =_xlfn.XLOOKUP(A15,Sheet1!A$2:A$800,Sheet1!G$2:G$800, "") -> Gas | F15: InChI=1S/C10H16/c1-7-4-5-8-6-9(7)10(8,2)3/h4,8-9H,5-6H2,1-3H3;InChI=1S/C10H16/c1-7-4-5-8-6-9(7)10(8,2)3/h8-9H,1,4-6H2,2-3H3;InChI=1S/C10H16/c1-7(2)10-5-4-8(3)9(10)6-10/h7,9H,3-6H2,1-2H3;InChI=1S/C10H16/c1-7-4-5-8-9(6-7)10(8,2)3/h4,8-9H,5-6H2,1-3H3
A16: LIMO | B16: C10H16 | C16: Limonene | D16: 136.26 | E16: =_xlfn.XLOOKUP(A16,Sheet1!A$2:A$800,Sheet1!G$2:G$800, "") -> Gas | F16: InChI=1S/C10H16/c1-8(2)10-6-4-9(3)5-7-10/h4,10H,1,5-7H2,2-3H3
A17: MTPO | C17: Terpinene, terpinolene, myrcene, ocimene, other monoterpenes | D17: 136.26 | E17: =_xlfn.XLOOKUP(A17,Sheet1!A$2:A$800,Sheet1!G$2:G$800, "") -> Gas | F17: InChI=1S/C10H16/c1-8(2)10-6-4-9(3)5-7-10/h4,7-8H,5-6H2,1-3H3;InChI=1S/C10H16/c1-8(2)10-6-4-9(3)5-7-10/h4,6,8H,5,7H2,1-3H3;InChI=1S/C10H16/c1-8(2)10-6-4-9(3)5-7-10/h4H,5-7H2,1-3H3;InChI=1S/C10H16/c1-5-10(4)8-6-7-9(2)3/h5,7H,1,4,6,8H2,2-3H3;InChI=1S/C10H16/c1-5-10(4)8-6-7-9(2)3/h5,7-8H,1,6H2,2-4H3/b10-8+;InChI=1S/C10H16/c1-5-10(4)8-6-7-9(2)3/h5,7-8H,1,6H2,2-4H3/b10-8-;InChI=1S/C10H16/c1-5-10(4)8-6-7-9(2)3/h5,8H,1-2,6-7H2,3-4H3/b10-8-;InChI=1S/C10H16/c1-5-10(4)8-6-7-9(2)3/h5,7-8H,1,6H2,2-4H3;InChI=1S/C10H14/c1-8(2)10-6-4-9(3)5-7-10/h4-8H,1-3H3;InChI=1S/C10H14/c1-8(2)10-7-5-4-6-9(10)3/h4-8H,1-3H3;InChI=1S/C10H14/c1-8(2)10-6-4-5-9(3)7-10/h4-8H,1-3H3
A18: OLND | B18: C10H16NO5 | C18: Monoterpene-derived NO3-alkene adduct | D18: 230.27 | E18: =_xlfn.XLOOKUP(A18,Sheet1!A$2:A$800,Sheet1!G$2:G$800, "") -> Gas | F18: InChI=1S/C10H16NO5/c1-7(2)8-4-5-10(3,16-14)9(6-8)15-11(12)13/h8-9H,1,4-6H2,2-3H3
A19: OLNN | B19: C10H16NO5 | C19: Monoterpene-derived NO3 adduct | D19: 230.27 | E19: =_xlfn.XLOOKUP(A19,Sheet1!A$2:A$800,Sheet1!G$2:G$800, "") -> Gas | F19: InChI=1S/C10H16NO5/c1-9(2)7-3-4-10(16-14,8(9)5-7)6-15-11(12)13/h7-8H,3-6H2,1-2H3;InChI=1S/C10H16NO5/c1-9(2)6-4-7(9)10(3,16-14)8(5-6)15-11(12)13/h6-8H,4-5H2,1-3H3;InChI=1S/C10H16NO5/c1-9(2)6-4-7(9)10(3,16-11(12)13)8(5-6)15-14/h6-8H,4-5H2,1-3H3;InChI=1S/C10H16NO5/c1-9(2)7-3-4-10(6-15-14,8(9)5-7)16-11(12)13/h7-8H,3-6H2,1-2H3
A20: LIMAL | B20: C10H16O2 | C20: Aldehyde from limonene | D20: 186.28 | E20: Gas | F20: InChI=1S/C10H16O2/c1-6(2)8-5-9(11)7(3)4-10(8)12/h4,6,8,10,12H,5H2,1-3H3/t8-,10+/m0/s1 InChI=1S/C10H16O2/c1-6(2)8-5-9(11)7(3)4-10(8)12/h4,6,8,10,12H,5H2,1-3H3/t8-,10-/m0/s1
A21: LIMKET | B21: C10H16O2 | C21: Ketone from limonene | D21: 186.28 | E21: Gas | F21: InChI=1S/C10H16O2/c1-6(2)8-5-9(11)7(3)4-10(8)12/h4,6,8,10,12H,5H2,1-3H3/t8-,10+/m0/s1 InChI=1S/C10H16O2/c1-6(2)8-5-9(11)7(3)4-10(8)12/h4,6,8,10,12H,5H2,1-3H3/t8-,10-/m0/s1
A22: PINAL | B22: C10H16O2 | C22: Pinonaldehyde | D22: 186.28 | E22: Gas | F22: InChI=1S/C10H16O2/c1-6(2)8-5-9(11)7(3)4-10(8)12/h4,6,8,10,12H,5H2,1-3H3/t8-,10+/m0/s1 InChI=1S/C10H16O2/c1-6(2)8-5-9(11)7(3)4-10(8)12/h4,6,8,10,12H,5H2,1-3H3/t8-,10-/m0/s1
A23: LIMKB | B23: C10H16O3 | C23: 2nd gen ketone from limonene | D23: 186.28 | E23: Gas | F23: InChI=1S/C10H16O3/c1-2-13-10(12)7-9(11)8-5-3-4-6-8/h8H,2-7H2,1H3
A24: MONITU | B24: C10H17NO4 | C24: Unsaturated 1st gen monoterpene organic nitrate | D24: 215.28 | E24: =_xlfn.XLOOKUP(A24,Sheet1!A$2:A$800,Sheet1!G$2:G$800, "") -> Gas | F24: InChI=1S/C10H17NO4/c1-7-4-5-8(6-9(7)12)10(2,3)15-11(13)14/h4,8-9,12H,5-6H2,1-3H3;InChI=1S/C10H17NO4/c1-10(2,15-11(13)14)9-5-3-8(7-12)4-6-9/h3,9,12H,4-7H2,1-2H3;InChI=1S/C10H17NO4/c1-7(2)8-4-5-10(3,12)9(6-8)15-11(13)14/h8-9,12H,1,4-6H2,2-3H3;InChI=1S/C10H17NO4/c1-7(2)8-4-5-10(3,9(12)6-8)15-11(13)14/h8-9,12H,1,4-6H2,2-3H3;InChI=1S/C10H17NO4/c1-8-3-5-9(6-4-8)10(2,7-12)15-11(13)14/h3,9,12H,4-7H2,1-2H3;InChI=1S/C10H17NO4/c1-7(12)4-5-8-9(15-11(13)14)6-10(8,2)3/h8-9H,4-6H2,1-3H3
A25: MONITS | B25: C10H17NO4 | C25: Saturated 1st gen monoterpene organic nitrate | D25: 215.28 | E25: =_xlfn.XLOOKUP(A25,Sheet1!A$2:A$800,Sheet1!G$2:G$800, "") -> Gas | F25: InChI=1S/C10H17NO4/c1-9(2)6-4-7(9)10(3,8(12)5-6)15-11(13)14/h6-8,12H,4-5H2,1-3H3;InChI=1S/C10H17NO4/c1-9(2)6-4-7(9)10(3,12)8(5-6)15-11(13)14/h6-8,12H,4-5H2,1-3H3;InChI=1S/C10H17NO5/c1-9(2)6-4-7(9)10(3,16-14)8(5-6)15-11(12)13/h6-8,14H,4-5H2,1-3H3;InChI=1S/C10H17NO5/c1-9(2)6-4-7(9)10(3,16-11(12)13)8(5-6)15-14/h6-8,14H,4-5H2,1-3H3;InChI=1S/C10H17NO4/c1-9(2)7-3-4-10(6-12,8(9)5-7)15-11(13)14/h7-8,12H,3-6H2,1-2H3;InChI=1S/C10H17NO4/c1-9(2)7-3-4-10(12,8(9)5-7)6-15-11(13)14/h7-8,12H,3-6H2,1-2H3;InChI=1S/C10H17NO5/c1-9(2)7-3-4-10(16-14,8(9)5-7)6-15-11(12)13/h7-8,14H,3-6H2,1-2H3;InChI=1S/C10H17NO5/c1-9(2)7-3-4-10(6-15-14,8(9)5-7)16-11(12)13/h7-8,14H,3-6H2,1-2H3
A26: LIMO2 | B26: C10H17O3 | C26: Peroxy radical from LIMO | D26: 185.27 | E26: =_xlfn.XLOOKUP(A26,Sheet1!A$2:A$800,Sheet1!G$2:G$800, "") -> Gas | F26: InChI=1S/C10H17O3/c1-7(2)8-4-5-10(3,13-12)9(11)6-8/h8-9,11H,1,4-6H2,2-3H3;InChI=1S/C10H17O3/c1-7(2)8-4-5-10(3,11)9(6-8)13-12/h8-9,11H,1,4-6H2,2-3H3; InChI=1S/C10H17O3/c1-8-3-5-9(6-4-8)10(2,7-11)13-12/h3,9,11H,4-7H2,1-2H3
A27: PIO2 | B27: C10H17O3 | C27: Peroxy radical from MTPA | D27: 185.27 | E27: =_xlfn.XLOOKUP(A27,Sheet1!A$2:A$800,Sheet1!G$2:G$800, "") -> Gas | F27: InChI=1S/C10H17O3/c1-9(2)6-4-7(9)10(3,13-12)8(11)5-6/h6-8,11H,4-5H2,1-3H3;InChI=1S/C10H17O3/c1-9(2)6-4-7(9)10(3,11)8(5-6)13-12/h6-8,11H,4-5H2,1-3H3;InChI=1S/C10H17O3/c1-9(2)7-3-4-10(6-11,13-12)8(9)5-7/h7-8,11H,3-6H2,1-2H3;InChI=1S/C10H17O3/c1-9(2)7-3-4-10(11,6-13-12)8(9)5-7/h7-8,11H,3-6H2,1-2H3;InChI=1S/C10H17O3/c1-10(2,13-12)9-5-3-8(7-11)4-6-9/h3,9,11H,4-7H2,1-2H3;InChI=1S/C10H17O3/c1-7(2)8-4-5-10(3,13-12)9(11)6-8/h8-9,11H,1,4-6H2,2-3H3;InChI=InChI=1S/C10H17O3/c1-7(11)4-5-8-9(13-12)6-10(8,2)3/h8-9H,4-6H2,1-3H3;1S/C10H17O3/c1-7(2)8-4-5-10(3,11)9(6-8)13-12/h8-9,11H,1,4-6H2,2-3H3;InChI=1S/C10H17O3/c1-8-3-5-9(6-4-8)10(2,7-11)13-12/h3,9,11H,4-7H2,1-2H3;
A28: LIMO2H | B28: C10H18O3 | C28: Acid from LIMO | D28: 186.28 | E28: Gas | F28: InChI=1S/C10H18O3/c1-2-13-9(12)10(8-11)6-4-3-5-7-10/h11H,2-8H2,1H3
A29: PINONIC | B29: C10H18O3 | C29: Pinonic acid | D29: 186.28 | E29: Gas | F29: InChI=1S/C10H18O3/c1-2-13-9(12)10(8-11)6-4-3-5-7-10/h11H,2-8H2,1H3
A30: PIP | B30: C10H18O3 | C30: Peroxide from MTPA | D30: 186.28 | E30: =_xlfn.XLOOKUP(A30,Sheet1!A$2:A$800,Sheet1!G$2:G$800, "") -> Gas | F30: InChI=1S/C10H18O3/c1-9(2)6-4-7(9)10(3,13-12)8(11)5-6/h6-8,11-12H,4-5H2,1-3H3;InChI=1S/C10H18O3/c1-9(2)6-4-7(9)10(3,11)8(5-6)13-12/h6-8,11-12H,4-5H2,1-3H3;InChI=1S/C10H18O3/c1-7-4-5-8(6-9(7)11)10(2,3)13-12/h4,8-9,11-12H,5-6H2,1-3H3;InChI=1S/C10H18O3/c1-9(2)7-3-4-10(6-11,13-12)8(9)5-7/h7-8,11-12H,3-6H2,1-2H3;InChI=1S/C10H18O3/c1-9(2)7-3-4-10(11,6-13-12)8(9)5-7/h7-8,11-12H,3-6H2,1-2H3;InChI=1S/C10H18O3/c1-10(2,13-12)9-5-3-8(7-11)4-6-9/h3,9,11-12H,4-7H2,1-2H3;InChI=1S/C10H18O3/c1-7(11)4-5-8-9(13-12)6-10(8,2)3/h8-9,12H,4-6H2,1-3H3
A31: LIMO3H | B31: C10H18O4 | C31: Peracid from LIMO | D31: 186.28 | E31: Gas | F31: InChI=1S/C10H18O4/c1-3-7-11-9(5-1)13-14-10-6-2-4-8-12-10/h9-10H,1-8H2
A32: PINO3H | B32: C10H18O4 | C32: Pinonic peracid | D32: 186.28 | E32: Gas | F32: InChI=1S/C10H18O4/c1-3-7-11-9(5-1)13-14-10-6-2-4-8-12-10/h9-10H,1-8H2
A33: NAP | B33: C10H8 | C33: Naphtalene/IVOC surrogate | D33: 128.18 | E33: =_xlfn.XLOOKUP(A33,Sheet1!A$2:A$800,Sheet1!G$2:G$800, "") -> Gas | F33: InChI=1S/C10H8/c1-2-6-10-8-4-3-7-9(10)5-1/h1-8H
A34: NRO2 | B34: C10H7O2 | C34: Peroxy radical from NAP oxidation | D34: 159.17 | E34: =_xlfn.XLOOKUP(A34,Sheet1!A$2:A$800,Sheet1!G$2:G$800, "") -> Gas | F34: InChI=1S/C10H9O3/c11-10-8-4-2-1-3-7(8)5-6-9(10)13-12/h1-6,9-11H
A35: H2402 | B35: C2Br2F4 | C35: Halon 2402 | D35: 259.82 | E35: =_xlfn.XLOOKUP(A35,Sheet1!A$2:A$800,Sheet1!G$2:G$800, "") -> Gas | F35: InChI=1S/C2Br2F4/c3-1(5,6)2(4,7)8
A36: CFC114 | B36: C2Cl2F4 | C36: CFC-114 | D36: 170.92 | E36: =_xlfn.XLOOKUP(A36,Sheet1!A$2:A$800,Sheet1!G$2:G$800, "") -> Gas | F36: InChI=1S/C2Cl2F4/c3-1(5,6)2(4,7)8
A37: CFC113 | B37: C2Cl3F3 | C37: CFC-113 | D37: 187.38 | E37: =_xlfn.XLOOKUP(A37,Sheet1!A$2:A$800,Sheet1!G$2:G$800, "") -> Gas | F37: InChI=1S/C2Cl3F3/c3-1(4,6)2(5,7)8
A38: CFC115 | B38: C2ClF5 | C38: CFC-115 | D38: 154.47 | E38: =_xlfn.XLOOKUP(A38,Sheet1!A$2:A$800,Sheet1!G$2:G$800, "") -> Gas | F38: InChI=1S/C2ClF5/c3-1(4,5)2(6,7)8
A39: C2H2 | B39: C2H2 | C39: Acetylene (aka Ethyne) | D39: 26.05 | E39: =_xlfn.XLOOKUP(A39,Sheet1!A$2:A$800,Sheet1!G$2:G$800, "") -> Gas | F39: InChI=1S/C2H2/c1-2/h1-2H
A40: GLYX | B40: CHOCHO | C40: Glyoxal | D40: 58.04 | E40: =_xlfn.XLOOKUP(A40,Sheet1!A$2:A$800,Sheet1!G$2:G$800, "") -> Gas | F40: InChI=1S/C2H2O2/c3-1-2-4/h1-2H
...
